Workbook

Sheet Start Here
A1: hona
A8: THE FIX & FLIP WORKBOOK
B11: Run a flip without having run one before.
B12: Answer the questions on Your Deal. Put six sold houses on Comps. Untick what this house does not need on Scope & Phases. Send the Bid Request to subs and type back what they quote. Everything else fills itself in.
A15: WHERE YOU ARE
B17: Step | C17: What it is | D17: Done
B18: 1. Your Deal | C18: Fourteen questions about the house, the money and your terms. | D18: =COUNTA('Your Deal'!$D$6:$D$40) -> 14 | E18: 14
B19: 2. Comps & Buy Box | C19: Three sold as-is, three sold renovated. Gives you your ceiling. | D19: =COUNT('Comps & Buy Box'!$C$8:$C$10)+COUNT('Comps & Buy Box'!$C$16:$C$18) -> 6 | E19: 6
B20: 3. Scope & Phases | C20: Untick anything this house does not need. | D20: =COUNTIF('Scope & Phases'!$D$8:$D$73,"x") -> 52 | E20: jobs
B21: 4. Bid Comparison | C21: What each sub quoted — price and days. | D21: =COUNTIF('Bid Comparison'!$N$8:$N$73,">0") -> 52 | E21: priced
A23: WHAT IT TELLS YOU
B25: Most you should pay | D25: ='Comps & Buy Box'!$D$33 -> 276826.14
B26: Rehab budget from your bids | D26: ='Budget & Schedule'!$D$5 -> 129325
B27: Cost per square foot | D27: ='Budget & Schedule'!$D$6 -> 69.52957
B28: Days on site | D28: ='Budget & Schedule'!$D$7 -> 155
B29: Extra cash you need between draws | D29: ='Cash & Float'!$F$21 -> 0
B32: Blue cells are yours to fill in. Grey cells calculate themselves — leave them alone.
B34: Need help? Email support@honafinancial.com with any question about this workbook.
B36: When the numbers are right, the last sheet hands your project straight to Hona — and every receipt you scan lands against them. honafinancial.com

Sheet Your Deal
A1: Your Deal
A2: Answer these in order. Everything else in this workbook fills itself in.
A5: THE PROPERTY
A7: 1. Property address | D7: 1421 E Cloud Rd, Queen Creek AZ
A8: Street, city, state
A9: 2. Square footage | D9: 1860
A10: Heated and cooled area only
A11: 3. What are you paying for it? | D11: 255000
A12: Purchase price. Leave blank if you have not offered yet.
A13: 4. How rough is it? | D13: Medium
A14: Light / Medium / Heavy / Rebuild — this pre-ticks your scope
A16: THE MONEY
A18: 5. How much are you borrowing? | D18: 310000
A19: Total loan amount including rehab draws
A20: 6. Interest rate | D20: 0.115
A21: Annual rate, e.g. 11.5%
A22: 7. Points | D22: 2
A23: Origination points charged at closing
A24: 8. Days from draw request until your lender funds | D24: 10
A25: Ask them. This drives how much cash you carry.
A26: 9. How much of your own cash can you put in? | D26: 60000
A27: Cash available for deposits and carry, not the down payment
A29: YOUR TERMS
A31: 10. When do you start? | D31: 46314
A32: First day of work on site
A33: 11. What do subs get up front? | D33: 0.5
A34: Arizona residential standard is 50% down, 50% on completion
A35: 12. Does your lender hold back a retainage? | D35: 0.1
A36: Percentage held from each draw until completion
A37: 13. Selling costs when you exit | D37: 0.08
A38: Agent commission plus closing. 8% is a common default.
A39: 14. What profit are you aiming for? | D39: 55000
A40: Your number, not a formula. This sets your maximum offer.
A43: Everything above is filled in with an example deal so you can see how it works. Replace it with yours.
A44: Need help? Email support@honafinancial.com with any question about this workbook.

Sheet Comps & Buy Box
A1: Comps & Buy Box
A2: Six sales tell you what this house is worth now, what it is worth finished, and the most you should pay.
A5: AS-IS COMPARABLES — WHAT HOUSES LIKE THIS SELL FOR BEFORE ANYONE TOUCHES THEM
A7: Address | B7: Sq ft | C7: Sold price | D7: $ / sq ft | E7: Notes
A8: 1188 E Silver Creek Rd | B8: 1795 | C8: 262000 | D8: =IFERROR(C8/B8,"") -> 145.961 | E8: Sold as-is, dated kitchen
A9: 22410 S 213th St | B9: 1902 | C9: 271000 | D9: =IFERROR(C9/B9,"") -> 142.4816 | E9: Estate sale, original baths
A10: 1640 W Kingman Loop | B10: 1748 | C10: 249000 | D10: =IFERROR(C10/B10,"") -> 142.44851 | E10: Investor purchase, roof issue
C11: Average $ / sq ft | D11: =IFERROR(AVERAGE(D8:D10),0) -> 143.63037
A13: FINISHED COMPARABLES — WHAT HOUSES LIKE THIS SELL FOR RENOVATED (YOUR ARV)
A15: Address | B15: Sq ft | C15: Sold price | D15: $ / sq ft | E15: Notes
A16: 1355 E Cloud Rd | B16: 1880 | C16: 529000 | D16: =IFERROR(C16/B16,"") -> 281.38298 | E16: Full reno, quartz + LVP
A17: 22188 S 214th Way | B17: 1815 | C17: 512000 | D17: =IFERROR(C17/B17,"") -> 282.09366 | E17: Updated 2025, new HVAC
A18: 1502 W Kingman Loop | B18: 1930 | C18: 545000 | D18: =IFERROR(C18/B18,"") -> 282.38342 | E18: Reno + pool resurface
C19: Average $ / sq ft | D19: =IFERROR(AVERAGE(D16:D18),0) -> 281.95335
A21: THE BUY BOX — THE MOST YOU SHOULD PAY FOR THIS HOUSE
A23: Walk a neighborhood, type a square footage above, and this tells you your ceiling before you make an offer.
A25: Estimated as-is value | D25: ='Your Deal'!$D$9*'Comps & Buy Box'!$D$11 -> 267152.49
A26: Estimated ARV (finished value) | D26: ='Your Deal'!$D$9*'Comps & Buy Box'!$D$19 -> 524433.24
A28: Less selling costs | D28: =-$D$26*'Your Deal'!$D$37 -> -41954.659
A29: Less rehab budget | D29: =-'Budget & Schedule'!$D$5 -> -129325
A30: Less loan carry and points | D30: =-(('Your Deal'!$D$18*'Your Deal'!$D$20)*('Budget & Schedule'!$D$8/12)+'Your Deal'!$D$18*('Your Deal'!$D$22/100)) -> -21327.436
A31: Less your target profit | D31: =-'Your Deal'!$D$39 -> -55000
A33: MAXIMUM YOU SHOULD PAY | D33: =$D$26-$D$26*'Your Deal'!$D$37-'Budget & Schedule'!$D$5-(('Your Deal'!$D$18*'Your Deal'!$D$20)*('Budget & Schedule'!$D$8/12)+'Your Deal'!$D$18*('Your Deal'!$D$22/100))-'Your Deal'!$D$39 -> 276826.14
A35: You are paying | D35: ='Your Deal'!$D$11 -> 255000
A36: Under / (over) your ceiling | D36: =IF('Your Deal'!$D$11=0,"",'Comps & Buy Box'!$D$33-'Your Deal'!$D$11) -> 21826.143
A38: Green means the deal clears your profit target at these numbers. Red means it does not.

Sheet Scope & Phases
A1: Scope & Phases
A2: Everything a flip can need is already listed. Untick what this house does not.
A6: Pre-ticked for a medium-scope flip. Put an x to include a job, clear the cell to drop it. Budget and days fill in from your bids.
A7: Ph | B7: Phase | C7: Category | D7: Use? | E7: Budget | F7: Days
A8: A | B8: Pre-Construction & General Conditions | C8: Permits & Plan Review | D8: x | E8: ='Bid Comparison'!N8 -> 1275 | F8: ='Bid Comparison'!O8 -> 12 | H8: =IF(D8="x",A8&"-"&COUNTIFS($A$8:A8,A8,$D$8:D8,"x"),"") -> A-1
A9: A | C9: Design & Drafting | E9: ='Bid Comparison'!N9 -> 0 | F9: ='Bid Comparison'!O9 -> 0 | H9: =IF(D9="x",A9&"-"&COUNTIFS($A$8:A9,A9,$D$8:D9,"x"),"")
A10: A | C10: Feasibility & Inspections | D10: x | E10: ='Bid Comparison'!N10 -> 750 | F10: ='Bid Comparison'!O10 -> 4 | H10: =IF(D10="x",A10&"-"&COUNTIFS($A$8:A10,A10,$D$8:D10,"x"),"") -> A-2
A11: A | C11: Impact & Utility Connection Fees | E11: ='Bid Comparison'!N11 -> 0 | F11: ='Bid Comparison'!O11 -> 0 | H11: =IF(D11="x",A11&"-"&COUNTIFS($A$8:A11,A11,$D$8:D11,"x"),"")
A12: A | C12: Insurance | D12: x | E12: ='Bid Comparison'!N12 -> 1675 | F12: ='Bid Comparison'!O12 -> 0 | H12: =IF(D12="x",A12&"-"&COUNTIFS($A$8:A12,A12,$D$8:D12,"x"),"") -> A-3
A13: A | C13: Utility Setup & Deposits | D13: x | E13: ='Bid Comparison'!N13 -> 400 | F13: ='Bid Comparison'!O13 -> 0 | H13: =IF(D13="x",A13&"-"&COUNTIFS($A$8:A13,A13,$D$8:D13,"x"),"") -> A-4
A14: A | C14: General Conditions & Supervision | D14: x | E14: ='Bid Comparison'!N14 -> 4225 | F14: ='Bid Comparison'!O14 -> 0 | H14: =IF(D14="x",A14&"-"&COUNTIFS($A$8:A14,A14,$D$8:D14,"x"),"") -> A-5
A15: A | C15: Contingency Reserve | D15: x | E15: ='Bid Comparison'!N15 -> 6600 | F15: ='Bid Comparison'!O15 -> 0 | H15: =IF(D15="x",A15&"-"&COUNTIFS($A$8:A15,A15,$D$8:D15,"x"),"") -> A-6
A16: 1 | B16: Demolition, Foundation & Underground | C16: Mobilization | D16: x | E16: ='Bid Comparison'!N16 -> 800 | F16: ='Bid Comparison'!O16 -> 2 | H16: =IF(D16="x",A16&"-"&COUNTIFS($A$8:A16,A16,$D$8:D16,"x"),"") -> 1-1
A17: 1 | C17: Hazmat Abatement | E17: ='Bid Comparison'!N17 -> 0 | F17: ='Bid Comparison'!O17 -> 0 | H17: =IF(D17="x",A17&"-"&COUNTIFS($A$8:A17,A17,$D$8:D17,"x"),"")
A18: 1 | C18: Selective Demolition | D18: x | E18: ='Bid Comparison'!N18 -> 4750 | F18: ='Bid Comparison'!O18 -> 6 | H18: =IF(D18="x",A18&"-"&COUNTIFS($A$8:A18,A18,$D$8:D18,"x"),"") -> 1-2
A19: 1 | C19: Excavation & Grading | E19: ='Bid Comparison'!N19 -> 0 | F19: ='Bid Comparison'!O19 -> 0 | H19: =IF(D19="x",A19&"-"&COUNTIFS($A$8:A19,A19,$D$8:D19,"x"),"")
A20: 1 | C20: Foundation & Slab | E20: ='Bid Comparison'!N20 -> 0 | F20: ='Bid Comparison'!O20 -> 0 | H20: =IF(D20="x",A20&"-"&COUNTIFS($A$8:A20,A20,$D$8:D20,"x"),"")
A21: 1 | C21: Underground Plumbing | E21: ='Bid Comparison'!N21 -> 0 | F21: ='Bid Comparison'!O21 -> 0 | H21: =IF(D21="x",A21&"-"&COUNTIFS($A$8:A21,A21,$D$8:D21,"x"),"")
A22: 1 | C22: Septic | E22: ='Bid Comparison'!N22 -> 0 | F22: ='Bid Comparison'!O22 -> 0 | H22: =IF(D22="x",A22&"-"&COUNTIFS($A$8:A22,A22,$D$8:D22,"x"),"")
A23: 1 | C23: Underground Electrical & Service | E23: ='Bid Comparison'!N23 -> 0 | F23: ='Bid Comparison'!O23 -> 0 | H23: =IF(D23="x",A23&"-"&COUNTIFS($A$8:A23,A23,$D$8:D23,"x"),"")
A24: 1 | C24: Pest & Soil Treatment | D24: x | E24: ='Bid Comparison'!N24 -> 450 | F24: ='Bid Comparison'!O24 -> 1 | H24: =IF(D24="x",A24&"-"&COUNTIFS($A$8:A24,A24,$D$8:D24,"x"),"") -> 1-3
A25: 2 | B25: Framing, Roofing & Rough MEP | C25: Framing Labor | D25: x | E25: ='Bid Comparison'!N25 -> 3350 | F25: ='Bid Comparison'!O25 -> 6 | H25: =IF(D25="x",A25&"-"&COUNTIFS($A$8:A25,A25,$D$8:D25,"x"),"") -> 2-1
A26: 2 | C26: Framing Material | D26: x | E26: ='Bid Comparison'!N26 -> 2725 | F26: ='Bid Comparison'!O26 -> 2 | H26: =IF(D26="x",A26&"-"&COUNTIFS($A$8:A26,A26,$D$8:D26,"x"),"") -> 2-2
A27: 2 | C27: Structural Steel & Beams | E27: ='Bid Comparison'!N27 -> 0 | F27: ='Bid Comparison'!O27 -> 0 | H27: =IF(D27="x",A27&"-"&COUNTIFS($A$8:A27,A27,$D$8:D27,"x"),"")
A28: 2 | C28: Roofing | D28: x | E28: ='Bid Comparison'!N28 -> 6950 | F28: ='Bid Comparison'!O28 -> 4 | H28: =IF(D28="x",A28&"-"&COUNTIFS($A$8:A28,A28,$D$8:D28,"x"),"") -> 2-3
A29: 2 | C29: Windows & Exterior Doors | D29: x | E29: ='Bid Comparison'!N29 -> 5450 | F29: ='Bid Comparison'!O29 -> 3 | H29: =IF(D29="x",A29&"-"&COUNTIFS($A$8:A29,A29,$D$8:D29,"x"),"") -> 2-4
A30: 2 | C30: Rough Plumbing | D30: x | E30: ='Bid Comparison'!N30 -> 3875 | F30: ='Bid Comparison'!O30 -> 5 | H30: =IF(D30="x",A30&"-"&COUNTIFS($A$8:A30,A30,$D$8:D30,"x"),"") -> 2-5
A31: 2 | C31: Rough Electrical | D31: x | E31: ='Bid Comparison'!N31 -> 4300 | F31: ='Bid Comparison'!O31 -> 6 | H31: =IF(D31="x",A31&"-"&COUNTIFS($A$8:A31,A31,$D$8:D31,"x"),"") -> 2-6
A32: 2 | C32: Rough HVAC | D32: x | E32: ='Bid Comparison'!N32 -> 5975 | F32: ='Bid Comparison'!O32 -> 4 | H32: =IF(D32="x",A32&"-"&COUNTIFS($A$8:A32,A32,$D$8:D32,"x"),"") -> 2-7
A33: 2 | C33: Low Voltage Rough | E33: ='Bid Comparison'!N33 -> 0 | F33: ='Bid Comparison'!O33 -> 0 | H33: =IF(D33="x",A33&"-"&COUNTIFS($A$8:A33,A33,$D$8:D33,"x"),"")
A34: 2 | C34: Rough Inspections | D34: x | E34: ='Bid Comparison'!N34 -> 300 | F34: ='Bid Comparison'!O34 -> 3 | H34: =IF(D34="x",A34&"-"&COUNTIFS($A$8:A34,A34,$D$8:D34,"x"),"") -> 2-8
A35: 3 | B35: Insulation, Drywall, Doors, Trim & Paint | C35: Insulation | D35: x | E35: ='Bid Comparison'!N35 -> 1850 | F35: ='Bid Comparison'!O35 -> 2 | H35: =IF(D35="x",A35&"-"&COUNTIFS($A$8:A35,A35,$D$8:D35,"x"),"") -> 3-1
A36: 3 | C36: Drywall | D36: x | E36: ='Bid Comparison'!N36 -> 5625 | F36: ='Bid Comparison'!O36 -> 8 | H36: =IF(D36="x",A36&"-"&COUNTIFS($A$8:A36,A36,$D$8:D36,"x"),"") -> 3-2
A37: 3 | C37: Interior Doors | D37: x | E37: ='Bid Comparison'!N37 -> 2025 | F37: ='Bid Comparison'!O37 -> 3 | H37: =IF(D37="x",A37&"-"&COUNTIFS($A$8:A37,A37,$D$8:D37,"x"),"") -> 3-3
A38: 3 | C38: Trim & Millwork | D38: x | E38: ='Bid Comparison'!N38 -> 2550 | F38: ='Bid Comparison'!O38 -> 4 | H38: =IF(D38="x",A38&"-"&COUNTIFS($A$8:A38,A38,$D$8:D38,"x"),"") -> 3-4
A39: 3 | C39: Stairs & Railings | E39: ='Bid Comparison'!N39 -> 0 | F39: ='Bid Comparison'!O39 -> 0 | H39: =IF(D39="x",A39&"-"&COUNTIFS($A$8:A39,A39,$D$8:D39,"x"),"")
A40: 3 | C40: Interior Paint | D40: x | E40: ='Bid Comparison'!N40 -> 4050 | F40: ='Bid Comparison'!O40 -> 5 | H40: =IF(D40="x",A40&"-"&COUNTIFS($A$8:A40,A40,$D$8:D40,"x"),"") -> 3-5
A41: 4 | B41: Cabinets & Countertops | C41: Kitchen Cabinets | D41: x | E41: ='Bid Comparison'!N41 -> 6075 | F41: ='Bid Comparison'!O41 -> 4 | H41: =IF(D41="x",A41&"-"&COUNTIFS($A$8:A41,A41,$D$8:D41,"x"),"") -> 4-1
A42: 4 | C42: Bath Vanities | D42: x | E42: ='Bid Comparison'!N42 -> 1625 | F42: ='Bid Comparison'!O42 -> 2 | H42: =IF(D42="x",A42&"-"&COUNTIFS($A$8:A42,A42,$D$8:D42,"x"),"") -> 4-2
A43: 4 | C43: Laundry & Utility Cabinets | D43: x | E43: ='Bid Comparison'!N43 -> 675 | F43: ='Bid Comparison'!O43 -> 1 | H43: =IF(D43="x",A43&"-"&COUNTIFS($A$8:A43,A43,$D$8:D43,"x"),"") -> 4-3
...

Sheet Bid Request
A1: Bid Request | H1: A — Pre-Construction & General Conditions
A2: Pick a phase, print this page, hand it to a sub. They fill in price and days. | H2: 1 — Demolition, Foundation & Underground
H3: 2 — Framing, Roofing & Rough MEP
H4: 3 — Insulation, Drywall, Doors, Trim & Paint
H5: 4 — Cabinets & Countertops
A6: Which phase are you sending out? | B6: 2 — Framing, Roofing & Rough MEP | C6: =HYPERLINK("mailto:?subject="&SUBSTITUTE(SUBSTITUTE("Bid request - "&$B$8&" - "&$B$6,"&","%26")," ","%20")&"&body="&SUBSTITUTE(SUBSTITUTE("Hi,"&"%0D%0A"&"%0D%0A"&"I am requesting a bid on the scope below for "&$B$8&"."&"%0D%0A"&"%0D%0A"&"Phase: "&$B$6&"%0D%0A"&"%0D%0A"&_xlfn.TEXTJOIN("%0D%0A",TRUE,A16:A27)&"%0D%0A"&"%0D%0A"&"Please reply with a price and the number of calendar days for each line."&"%0D%0A"&"%0D%0A"&"Terms: a deposit at start of work with the balance on completion. Days are calendar days. Price includes labor and materials unless you note otherwise. A signed lien waiver is required with each payment."&"%0D%0A"&"%0D%0A"&"Thank you,","&","%26")," ","%20"),"✉ Email this bid request") -> #VALUE! | H6: 5 — Tile & Flooring
C7: Opens your mail app with the whole request written. Add their address and send. | H7: 6 — Exterior & Landscaping
A8: Property | B8: ='Your Deal'!$D$7 -> 1421 E Cloud Rd, Queen Creek AZ | H8: 7 — MEP Finishes, Glass & Appliances
A9: Contractor / sub | H9: 8 — Punch, Carpet & Final Clean
A10: Date sent
A11: Please return by
A13: SCOPE OF WORK
A15: Category | B15: Describe the work (you fill this in) | C15: Your price | D15: Days
A16: =IFERROR(INDEX('Scope & Phases'!$C$8:$C$73,MATCH(LEFT($B$6,FIND(" ",$B$6&" ")-1)&"-"&1,'Scope & Phases'!$H$8:$H$73,0)),"") -> Framing Labor
A17: =IFERROR(INDEX('Scope & Phases'!$C$8:$C$73,MATCH(LEFT($B$6,FIND(" ",$B$6&" ")-1)&"-"&2,'Scope & Phases'!$H$8:$H$73,0)),"") -> Framing Material
A18: =IFERROR(INDEX('Scope & Phases'!$C$8:$C$73,MATCH(LEFT($B$6,FIND(" ",$B$6&" ")-1)&"-"&3,'Scope & Phases'!$H$8:$H$73,0)),"") -> Roofing
A19: =IFERROR(INDEX('Scope & Phases'!$C$8:$C$73,MATCH(LEFT($B$6,FIND(" ",$B$6&" ")-1)&"-"&4,'Scope & Phases'!$H$8:$H$73,0)),"") -> Windows & Exterior Doors
A20: =IFERROR(INDEX('Scope & Phases'!$C$8:$C$73,MATCH(LEFT($B$6,FIND(" ",$B$6&" ")-1)&"-"&5,'Scope & Phases'!$H$8:$H$73,0)),"") -> Rough Plumbing
A21: =IFERROR(INDEX('Scope & Phases'!$C$8:$C$73,MATCH(LEFT($B$6,FIND(" ",$B$6&" ")-1)&"-"&6,'Scope & Phases'!$H$8:$H$73,0)),"") -> Rough Electrical
A22: =IFERROR(INDEX('Scope & Phases'!$C$8:$C$73,MATCH(LEFT($B$6,FIND(" ",$B$6&" ")-1)&"-"&7,'Scope & Phases'!$H$8:$H$73,0)),"") -> Rough HVAC
A23: =IFERROR(INDEX('Scope & Phases'!$C$8:$C$73,MATCH(LEFT($B$6,FIND(" ",$B$6&" ")-1)&"-"&8,'Scope & Phases'!$H$8:$H$73,0)),"") -> Rough Inspections
A24: =IFERROR(INDEX('Scope & Phases'!$C$8:$C$73,MATCH(LEFT($B$6,FIND(" ",$B$6&" ")-1)&"-"&9,'Scope & Phases'!$H$8:$H$73,0)),"")
A25: =IFERROR(INDEX('Scope & Phases'!$C$8:$C$73,MATCH(LEFT($B$6,FIND(" ",$B$6&" ")-1)&"-"&10,'Scope & Phases'!$H$8:$H$73,0)),"")
A26: =IFERROR(INDEX('Scope & Phases'!$C$8:$C$73,MATCH(LEFT($B$6,FIND(" ",$B$6&" ")-1)&"-"&11,'Scope & Phases'!$H$8:$H$73,0)),"")
A27: =IFERROR(INDEX('Scope & Phases'!$C$8:$C$73,MATCH(LEFT($B$6,FIND(" ",$B$6&" ")-1)&"-"&12,'Scope & Phases'!$H$8:$H$73,0)),"")
B29: TOTAL BID | C29: =SUM(C16:C27) -> 0 | D29: =IFERROR(MAX(D16:D27),0) -> 0
A31: TERMS
A33: • Deposit at start of work: this project pays a deposit, with the balance due on completion.
A34: • Days above are calendar days from the day you start, not working days.
A35: • Price is for labor and materials unless you note otherwise in the description.
A36: • A signed lien waiver is required with each payment.
A38: Questions about this request? support@honafinancial.com

Sheet Bid Comparison
A1: Bid Comparison
A2: Type in what each sub quoted. The cheapest is used unless you pick another.
A6: One bid gets you a budget. Three gets you the truth. Days come from the sub, not from you — leave Days at 0 for anything that runs the whole job, like supervision, insurance or a reserve.
A7: Ph | B7: Category | C7: Use? | D7: Bid 1 — company | E7: Bid 1 $ | F7: Days | G7: Bid 2 — company | H7: Bid 2 $ | I7: Days | J7: Bid 3 — company | K7: Bid 3 $ | L7: Days | M7: Pick | N7: Chosen $ | O7: Days | P7: Chosen sub
A8: A | B8: Permits & Plan Review | C8: ='Scope & Phases'!D8 -> x | D8: City of Queen Creek | E8: 1275 | F8: 12 | N8: =IFERROR(IF($C8<>"x",0,IF($M8=1,E8,IF($M8=2,H8,IF($M8=3,K8,IF(COUNT(E8,H8,K8)=0,0,MIN(IF(E8>0,E8,1E+99),IF(H8>0,H8,1E+99),IF(K8>0,K8,1E+99))))))),0) -> 1275 | O8: =IFERROR(IF($C8<>"x",0,IF($M8=1,F8,IF($M8=2,I8,IF($M8=3,L8,IF(E8=IF(COUNT(E8,H8,K8)=0,0,MIN(IF(E8>0,E8,1E+99),IF(H8>0,H8,1E+99),IF(K8>0,K8,1E+99))),F8,IF(H8=IF(COUNT(E8,H8,K8)=0,0,MIN(IF(E8>0,E8,1E+99),IF(H8>0,H8,1E+99),IF(K8>0,K8,1E+99))),I8,L8)))))),0) -> 12 | P8: =IFERROR(IF($C8<>"x",0,IF($M8=1,D8,IF($M8=2,G8,IF($M8=3,J8,IF(E8=IF(COUNT(E8,H8,K8)=0,0,MIN(IF(E8>0,E8,1E+99),IF(H8>0,H8,1E+99),IF(K8>0,K8,1E+99))),D8,IF(H8=IF(COUNT(E8,H8,K8)=0,0,MIN(IF(E8>0,E8,1E+99),IF(H8>0,H8,1E+99),IF(K8>0,K8,1E+99))),G8,J8)))))),0) -> City of Queen Creek
A9: A | B9: Design & Drafting | C9: ='Scope & Phases'!D9 -> 0 | N9: =IFERROR(IF($C9<>"x",0,IF($M9=1,E9,IF($M9=2,H9,IF($M9=3,K9,IF(COUNT(E9,H9,K9)=0,0,MIN(IF(E9>0,E9,1E+99),IF(H9>0,H9,1E+99),IF(K9>0,K9,1E+99))))))),0) -> 0 | O9: =IFERROR(IF($C9<>"x",0,IF($M9=1,F9,IF($M9=2,I9,IF($M9=3,L9,IF(E9=IF(COUNT(E9,H9,K9)=0,0,MIN(IF(E9>0,E9,1E+99),IF(H9>0,H9,1E+99),IF(K9>0,K9,1E+99))),F9,IF(H9=IF(COUNT(E9,H9,K9)=0,0,MIN(IF(E9>0,E9,1E+99),IF(H9>0,H9,1E+99),IF(K9>0,K9,1E+99))),I9,L9)))))),0) -> 0 | P9: =IFERROR(IF($C9<>"x",0,IF($M9=1,D9,IF($M9=2,G9,IF($M9=3,J9,IF(E9=IF(COUNT(E9,H9,K9)=0,0,MIN(IF(E9>0,E9,1E+99),IF(H9>0,H9,1E+99),IF(K9>0,K9,1E+99))),D9,IF(H9=IF(COUNT(E9,H9,K9)=0,0,MIN(IF(E9>0,E9,1E+99),IF(H9>0,H9,1E+99),IF(K9>0,K9,1E+99))),G9,J9)))))),0) -> 0
A10: A | B10: Feasibility & Inspections | C10: ='Scope & Phases'!D10 -> x | E10: 750 | F10: 4 | N10: =IFERROR(IF($C10<>"x",0,IF($M10=1,E10,IF($M10=2,H10,IF($M10=3,K10,IF(COUNT(E10,H10,K10)=0,0,MIN(IF(E10>0,E10,1E+99),IF(H10>0,H10,1E+99),IF(K10>0,K10,1E+99))))))),0) -> 750 | O10: =IFERROR(IF($C10<>"x",0,IF($M10=1,F10,IF($M10=2,I10,IF($M10=3,L10,IF(E10=IF(COUNT(E10,H10,K10)=0,0,MIN(IF(E10>0,E10,1E+99),IF(H10>0,H10,1E+99),IF(K10>0,K10,1E+99))),F10,IF(H10=IF(COUNT(E10,H10,K10)=0,0,MIN(IF(E10>0,E10,1E+99),IF(H10>0,H10,1E+99),IF(K10>0,K10,1E+99))),I10,L10)))))),0) -> 4 | P10: =IFERROR(IF($C10<>"x",0,IF($M10=1,D10,IF($M10=2,G10,IF($M10=3,J10,IF(E10=IF(COUNT(E10,H10,K10)=0,0,MIN(IF(E10>0,E10,1E+99),IF(H10>0,H10,1E+99),IF(K10>0,K10,1E+99))),D10,IF(H10=IF(COUNT(E10,H10,K10)=0,0,MIN(IF(E10>0,E10,1E+99),IF(H10>0,H10,1E+99),IF(K10>0,K10,1E+99))),G10,J10)))))),0) -> 0
A11: A | B11: Impact & Utility Connection Fees | C11: ='Scope & Phases'!D11 -> 0 | N11: =IFERROR(IF($C11<>"x",0,IF($M11=1,E11,IF($M11=2,H11,IF($M11=3,K11,IF(COUNT(E11,H11,K11)=0,0,MIN(IF(E11>0,E11,1E+99),IF(H11>0,H11,1E+99),IF(K11>0,K11,1E+99))))))),0) -> 0 | O11: =IFERROR(IF($C11<>"x",0,IF($M11=1,F11,IF($M11=2,I11,IF($M11=3,L11,IF(E11=IF(COUNT(E11,H11,K11)=0,0,MIN(IF(E11>0,E11,1E+99),IF(H11>0,H11,1E+99),IF(K11>0,K11,1E+99))),F11,IF(H11=IF(COUNT(E11,H11,K11)=0,0,MIN(IF(E11>0,E11,1E+99),IF(H11>0,H11,1E+99),IF(K11>0,K11,1E+99))),I11,L11)))))),0) -> 0 | P11: =IFERROR(IF($C11<>"x",0,IF($M11=1,D11,IF($M11=2,G11,IF($M11=3,J11,IF(E11=IF(COUNT(E11,H11,K11)=0,0,MIN(IF(E11>0,E11,1E+99),IF(H11>0,H11,1E+99),IF(K11>0,K11,1E+99))),D11,IF(H11=IF(COUNT(E11,H11,K11)=0,0,MIN(IF(E11>0,E11,1E+99),IF(H11>0,H11,1E+99),IF(K11>0,K11,1E+99))),G11,J11)))))),0) -> 0
A12: A | B12: Insurance | C12: ='Scope & Phases'!D12 -> x | D12: Hartford | E12: 1675 | F12: 0 | N12: =IFERROR(IF($C12<>"x",0,IF($M12=1,E12,IF($M12=2,H12,IF($M12=3,K12,IF(COUNT(E12,H12,K12)=0,0,MIN(IF(E12>0,E12,1E+99),IF(H12>0,H12,1E+99),IF(K12>0,K12,1E+99))))))),0) -> 1675 | O12: =IFERROR(IF($C12<>"x",0,IF($M12=1,F12,IF($M12=2,I12,IF($M12=3,L12,IF(E12=IF(COUNT(E12,H12,K12)=0,0,MIN(IF(E12>0,E12,1E+99),IF(H12>0,H12,1E+99),IF(K12>0,K12,1E+99))),F12,IF(H12=IF(COUNT(E12,H12,K12)=0,0,MIN(IF(E12>0,E12,1E+99),IF(H12>0,H12,1E+99),IF(K12>0,K12,1E+99))),I12,L12)))))),0) -> 0 | P12: =IFERROR(IF($C12<>"x",0,IF($M12=1,D12,IF($M12=2,G12,IF($M12=3,J12,IF(E12=IF(COUNT(E12,H12,K12)=0,0,MIN(IF(E12>0,E12,1E+99),IF(H12>0,H12,1E+99),IF(K12>0,K12,1E+99))),D12,IF(H12=IF(COUNT(E12,H12,K12)=0,0,MIN(IF(E12>0,E12,1E+99),IF(H12>0,H12,1E+99),IF(K12>0,K12,1E+99))),G12,J12)))))),0) -> Hartford
A13: A | B13: Utility Setup & Deposits | C13: ='Scope & Phases'!D13 -> x | E13: 400 | F13: 0 | N13: =IFERROR(IF($C13<>"x",0,IF($M13=1,E13,IF($M13=2,H13,IF($M13=3,K13,IF(COUNT(E13,H13,K13)=0,0,MIN(IF(E13>0,E13,1E+99),IF(H13>0,H13,1E+99),IF(K13>0,K13,1E+99))))))),0) -> 400 | O13: =IFERROR(IF($C13<>"x",0,IF($M13=1,F13,IF($M13=2,I13,IF($M13=3,L13,IF(E13=IF(COUNT(E13,H13,K13)=0,0,MIN(IF(E13>0,E13,1E+99),IF(H13>0,H13,1E+99),IF(K13>0,K13,1E+99))),F13,IF(H13=IF(COUNT(E13,H13,K13)=0,0,MIN(IF(E13>0,E13,1E+99),IF(H13>0,H13,1E+99),IF(K13>0,K13,1E+99))),I13,L13)))))),0) -> 0 | P13: =IFERROR(IF($C13<>"x",0,IF($M13=1,D13,IF($M13=2,G13,IF($M13=3,J13,IF(E13=IF(COUNT(E13,H13,K13)=0,0,MIN(IF(E13>0,E13,1E+99),IF(H13>0,H13,1E+99),IF(K13>0,K13,1E+99))),D13,IF(H13=IF(COUNT(E13,H13,K13)=0,0,MIN(IF(E13>0,E13,1E+99),IF(H13>0,H13,1E+99),IF(K13>0,K13,1E+99))),G13,J13)))))),0) -> 0
A14: A | B14: General Conditions & Supervision | C14: ='Scope & Phases'!D14 -> x | E14: 4225 | F14: 0 | N14: =IFERROR(IF($C14<>"x",0,IF($M14=1,E14,IF($M14=2,H14,IF($M14=3,K14,IF(COUNT(E14,H14,K14)=0,0,MIN(IF(E14>0,E14,1E+99),IF(H14>0,H14,1E+99),IF(K14>0,K14,1E+99))))))),0) -> 4225 | O14: =IFERROR(IF($C14<>"x",0,IF($M14=1,F14,IF($M14=2,I14,IF($M14=3,L14,IF(E14=IF(COUNT(E14,H14,K14)=0,0,MIN(IF(E14>0,E14,1E+99),IF(H14>0,H14,1E+99),IF(K14>0,K14,1E+99))),F14,IF(H14=IF(COUNT(E14,H14,K14)=0,0,MIN(IF(E14>0,E14,1E+99),IF(H14>0,H14,1E+99),IF(K14>0,K14,1E+99))),I14,L14)))))),0) -> 0 | P14: =IFERROR(IF($C14<>"x",0,IF($M14=1,D14,IF($M14=2,G14,IF($M14=3,J14,IF(E14=IF(COUNT(E14,H14,K14)=0,0,MIN(IF(E14>0,E14,1E+99),IF(H14>0,H14,1E+99),IF(K14>0,K14,1E+99))),D14,IF(H14=IF(COUNT(E14,H14,K14)=0,0,MIN(IF(E14>0,E14,1E+99),IF(H14>0,H14,1E+99),IF(K14>0,K14,1E+99))),G14,J14)))))),0) -> 0
A15: A | B15: Contingency Reserve | C15: ='Scope & Phases'!D15 -> x | E15: 6600 | F15: 0 | N15: =IFERROR(IF($C15<>"x",0,IF($M15=1,E15,IF($M15=2,H15,IF($M15=3,K15,IF(COUNT(E15,H15,K15)=0,0,MIN(IF(E15>0,E15,1E+99),IF(H15>0,H15,1E+99),IF(K15>0,K15,1E+99))))))),0) -> 6600 | O15: =IFERROR(IF($C15<>"x",0,IF($M15=1,F15,IF($M15=2,I15,IF($M15=3,L15,IF(E15=IF(COUNT(E15,H15,K15)=0,0,MIN(IF(E15>0,E15,1E+99),IF(H15>0,H15,1E+99),IF(K15>0,K15,1E+99))),F15,IF(H15=IF(COUNT(E15,H15,K15)=0,0,MIN(IF(E15>0,E15,1E+99),IF(H15>0,H15,1E+99),IF(K15>0,K15,1E+99))),I15,L15)))))),0) -> 0 | P15: =IFERROR(IF($C15<>"x",0,IF($M15=1,D15,IF($M15=2,G15,IF($M15=3,J15,IF(E15=IF(COUNT(E15,H15,K15)=0,0,MIN(IF(E15>0,E15,1E+99),IF(H15>0,H15,1E+99),IF(K15>0,K15,1E+99))),D15,IF(H15=IF(COUNT(E15,H15,K15)=0,0,MIN(IF(E15>0,E15,1E+99),IF(H15>0,H15,1E+99),IF(K15>0,K15,1E+99))),G15,J15)))))),0) -> 0
A16: 1 | B16: Mobilization | C16: ='Scope & Phases'!D16 -> x | E16: 800 | F16: 2 | N16: =IFERROR(IF($C16<>"x",0,IF($M16=1,E16,IF($M16=2,H16,IF($M16=3,K16,IF(COUNT(E16,H16,K16)=0,0,MIN(IF(E16>0,E16,1E+99),IF(H16>0,H16,1E+99),IF(K16>0,K16,1E+99))))))),0) -> 800 | O16: =IFERROR(IF($C16<>"x",0,IF($M16=1,F16,IF($M16=2,I16,IF($M16=3,L16,IF(E16=IF(COUNT(E16,H16,K16)=0,0,MIN(IF(E16>0,E16,1E+99),IF(H16>0,H16,1E+99),IF(K16>0,K16,1E+99))),F16,IF(H16=IF(COUNT(E16,H16,K16)=0,0,MIN(IF(E16>0,E16,1E+99),IF(H16>0,H16,1E+99),IF(K16>0,K16,1E+99))),I16,L16)))))),0) -> 2 | P16: =IFERROR(IF($C16<>"x",0,IF($M16=1,D16,IF($M16=2,G16,IF($M16=3,J16,IF(E16=IF(COUNT(E16,H16,K16)=0,0,MIN(IF(E16>0,E16,1E+99),IF(H16>0,H16,1E+99),IF(K16>0,K16,1E+99))),D16,IF(H16=IF(COUNT(E16,H16,K16)=0,0,MIN(IF(E16>0,E16,1E+99),IF(H16>0,H16,1E+99),IF(K16>0,K16,1E+99))),G16,J16)))))),0) -> 0
A17: 1 | B17: Hazmat Abatement | C17: ='Scope & Phases'!D17 -> 0 | N17: =IFERROR(IF($C17<>"x",0,IF($M17=1,E17,IF($M17=2,H17,IF($M17=3,K17,IF(COUNT(E17,H17,K17)=0,0,MIN(IF(E17>0,E17,1E+99),IF(H17>0,H17,1E+99),IF(K17>0,K17,1E+99))))))),0) -> 0 | O17: =IFERROR(IF($C17<>"x",0,IF($M17=1,F17,IF($M17=2,I17,IF($M17=3,L17,IF(E17=IF(COUNT(E17,H17,K17)=0,0,MIN(IF(E17>0,E17,1E+99),IF(H17>0,H17,1E+99),IF(K17>0,K17,1E+99))),F17,IF(H17=IF(COUNT(E17,H17,K17)=0,0,MIN(IF(E17>0,E17,1E+99),IF(H17>0,H17,1E+99),IF(K17>0,K17,1E+99))),I17,L17)))))),0) -> 0 | P17: =IFERROR(IF($C17<>"x",0,IF($M17=1,D17,IF($M17=2,G17,IF($M17=3,J17,IF(E17=IF(COUNT(E17,H17,K17)=0,0,MIN(IF(E17>0,E17,1E+99),IF(H17>0,H17,1E+99),IF(K17>0,K17,1E+99))),D17,IF(H17=IF(COUNT(E17,H17,K17)=0,0,MIN(IF(E17>0,E17,1E+99),IF(H17>0,H17,1E+99),IF(K17>0,K17,1E+99))),G17,J17)))))),0) -> 0
A18: 1 | B18: Selective Demolition | C18: ='Scope & Phases'!D18 -> x | D18: Demo Pros LLC | E18: 4750 | F18: 6 | N18: =IFERROR(IF($C18<>"x",0,IF($M18=1,E18,IF($M18=2,H18,IF($M18=3,K18,IF(COUNT(E18,H18,K18)=0,0,MIN(IF(E18>0,E18,1E+99),IF(H18>0,H18,1E+99),IF(K18>0,K18,1E+99))))))),0) -> 4750 | O18: =IFERROR(IF($C18<>"x",0,IF($M18=1,F18,IF($M18=2,I18,IF($M18=3,L18,IF(E18=IF(COUNT(E18,H18,K18)=0,0,MIN(IF(E18>0,E18,1E+99),IF(H18>0,H18,1E+99),IF(K18>0,K18,1E+99))),F18,IF(H18=IF(COUNT(E18,H18,K18)=0,0,MIN(IF(E18>0,E18,1E+99),IF(H18>0,H18,1E+99),IF(K18>0,K18,1E+99))),I18,L18)))))),0) -> 6 | P18: =IFERROR(IF($C18<>"x",0,IF($M18=1,D18,IF($M18=2,G18,IF($M18=3,J18,IF(E18=IF(COUNT(E18,H18,K18)=0,0,MIN(IF(E18>0,E18,1E+99),IF(H18>0,H18,1E+99),IF(K18>0,K18,1E+99))),D18,IF(H18=IF(COUNT(E18,H18,K18)=0,0,MIN(IF(E18>0,E18,1E+99),IF(H18>0,H18,1E+99),IF(K18>0,K18,1E+99))),G18,J18)))))),0) -> Demo Pros LLC
A19: 1 | B19: Excavation & Grading | C19: ='Scope & Phases'!D19 -> 0 | N19: =IFERROR(IF($C19<>"x",0,IF($M19=1,E19,IF($M19=2,H19,IF($M19=3,K19,IF(COUNT(E19,H19,K19)=0,0,MIN(IF(E19>0,E19,1E+99),IF(H19>0,H19,1E+99),IF(K19>0,K19,1E+99))))))),0) -> 0 | O19: =IFERROR(IF($C19<>"x",0,IF($M19=1,F19,IF($M19=2,I19,IF($M19=3,L19,IF(E19=IF(COUNT(E19,H19,K19)=0,0,MIN(IF(E19>0,E19,1E+99),IF(H19>0,H19,1E+99),IF(K19>0,K19,1E+99))),F19,IF(H19=IF(COUNT(E19,H19,K19)=0,0,MIN(IF(E19>0,E19,1E+99),IF(H19>0,H19,1E+99),IF(K19>0,K19,1E+99))),I19,L19)))))),0) -> 0 | P19: =IFERROR(IF($C19<>"x",0,IF($M19=1,D19,IF($M19=2,G19,IF($M19=3,J19,IF(E19=IF(COUNT(E19,H19,K19)=0,0,MIN(IF(E19>0,E19,1E+99),IF(H19>0,H19,1E+99),IF(K19>0,K19,1E+99))),D19,IF(H19=IF(COUNT(E19,H19,K19)=0,0,MIN(IF(E19>0,E19,1E+99),IF(H19>0,H19,1E+99),IF(K19>0,K19,1E+99))),G19,J19)))))),0) -> 0
A20: 1 | B20: Foundation & Slab | C20: ='Scope & Phases'!D20 -> 0 | N20: =IFERROR(IF($C20<>"x",0,IF($M20=1,E20,IF($M20=2,H20,IF($M20=3,K20,IF(COUNT(E20,H20,K20)=0,0,MIN(IF(E20>0,E20,1E+99),IF(H20>0,H20,1E+99),IF(K20>0,K20,1E+99))))))),0) -> 0 | O20: =IFERROR(IF($C20<>"x",0,IF($M20=1,F20,IF($M20=2,I20,IF($M20=3,L20,IF(E20=IF(COUNT(E20,H20,K20)=0,0,MIN(IF(E20>0,E20,1E+99),IF(H20>0,H20,1E+99),IF(K20>0,K20,1E+99))),F20,IF(H20=IF(COUNT(E20,H20,K20)=0,0,MIN(IF(E20>0,E20,1E+99),IF(H20>0,H20,1E+99),IF(K20>0,K20,1E+99))),I20,L20)))))),0) -> 0 | P20: =IFERROR(IF($C20<>"x",0,IF($M20=1,D20,IF($M20=2,G20,IF($M20=3,J20,IF(E20=IF(COUNT(E20,H20,K20)=0,0,MIN(IF(E20>0,E20,1E+99),IF(H20>0,H20,1E+99),IF(K20>0,K20,1E+99))),D20,IF(H20=IF(COUNT(E20,H20,K20)=0,0,MIN(IF(E20>0,E20,1E+99),IF(H20>0,H20,1E+99),IF(K20>0,K20,1E+99))),G20,J20)))))),0) -> 0
A21: 1 | B21: Underground Plumbing | C21: ='Scope & Phases'!D21 -> 0 | N21: =IFERROR(IF($C21<>"x",0,IF($M21=1,E21,IF($M21=2,H21,IF($M21=3,K21,IF(COUNT(E21,H21,K21)=0,0,MIN(IF(E21>0,E21,1E+99),IF(H21>0,H21,1E+99),IF(K21>0,K21,1E+99))))))),0) -> 0 | O21: =IFERROR(IF($C21<>"x",0,IF($M21=1,F21,IF($M21=2,I21,IF($M21=3,L21,IF(E21=IF(COUNT(E21,H21,K21)=0,0,MIN(IF(E21>0,E21,1E+99),IF(H21>0,H21,1E+99),IF(K21>0,K21,1E+99))),F21,IF(H21=IF(COUNT(E21,H21,K21)=0,0,MIN(IF(E21>0,E21,1E+99),IF(H21>0,H21,1E+99),IF(K21>0,K21,1E+99))),I21,L21)))))),0) -> 0 | P21: =IFERROR(IF($C21<>"x",0,IF($M21=1,D21,IF($M21=2,G21,IF($M21=3,J21,IF(E21=IF(COUNT(E21,H21,K21)=0,0,MIN(IF(E21>0,E21,1E+99),IF(H21>0,H21,1E+99),IF(K21>0,K21,1E+99))),D21,IF(H21=IF(COUNT(E21,H21,K21)=0,0,MIN(IF(E21>0,E21,1E+99),IF(H21>0,H21,1E+99),IF(K21>0,K21,1E+99))),G21,J21)))))),0) -> 0
A22: 1 | B22: Septic | C22: ='Scope & Phases'!D22 -> 0 | N22: =IFERROR(IF($C22<>"x",0,IF($M22=1,E22,IF($M22=2,H22,IF($M22=3,K22,IF(COUNT(E22,H22,K22)=0,0,MIN(IF(E22>0,E22,1E+99),IF(H22>0,H22,1E+99),IF(K22>0,K22,1E+99))))))),0) -> 0 | O22: =IFERROR(IF($C22<>"x",0,IF($M22=1,F22,IF($M22=2,I22,IF($M22=3,L22,IF(E22=IF(COUNT(E22,H22,K22)=0,0,MIN(IF(E22>0,E22,1E+99),IF(H22>0,H22,1E+99),IF(K22>0,K22,1E+99))),F22,IF(H22=IF(COUNT(E22,H22,K22)=0,0,MIN(IF(E22>0,E22,1E+99),IF(H22>0,H22,1E+99),IF(K22>0,K22,1E+99))),I22,L22)))))),0) -> 0 | P22: =IFERROR(IF($C22<>"x",0,IF($M22=1,D22,IF($M22=2,G22,IF($M22=3,J22,IF(E22=IF(COUNT(E22,H22,K22)=0,0,MIN(IF(E22>0,E22,1E+99),IF(H22>0,H22,1E+99),IF(K22>0,K22,1E+99))),D22,IF(H22=IF(COUNT(E22,H22,K22)=0,0,MIN(IF(E22>0,E22,1E+99),IF(H22>0,H22,1E+99),IF(K22>0,K22,1E+99))),G22,J22)))))),0) -> 0
A23: 1 | B23: Underground Electrical & Service | C23: ='Scope & Phases'!D23 -> 0 | N23: =IFERROR(IF($C23<>"x",0,IF($M23=1,E23,IF($M23=2,H23,IF($M23=3,K23,IF(COUNT(E23,H23,K23)=0,0,MIN(IF(E23>0,E23,1E+99),IF(H23>0,H23,1E+99),IF(K23>0,K23,1E+99))))))),0) -> 0 | O23: =IFERROR(IF($C23<>"x",0,IF($M23=1,F23,IF($M23=2,I23,IF($M23=3,L23,IF(E23=IF(COUNT(E23,H23,K23)=0,0,MIN(IF(E23>0,E23,1E+99),IF(H23>0,H23,1E+99),IF(K23>0,K23,1E+99))),F23,IF(H23=IF(COUNT(E23,H23,K23)=0,0,MIN(IF(E23>0,E23,1E+99),IF(H23>0,H23,1E+99),IF(K23>0,K23,1E+99))),I23,L23)))))),0) -> 0 | P23: =IFERROR(IF($C23<>"x",0,IF($M23=1,D23,IF($M23=2,G23,IF($M23=3,J23,IF(E23=IF(COUNT(E23,H23,K23)=0,0,MIN(IF(E23>0,E23,1E+99),IF(H23>0,H23,1E+99),IF(K23>0,K23,1E+99))),D23,IF(H23=IF(COUNT(E23,H23,K23)=0,0,MIN(IF(E23>0,E23,1E+99),IF(H23>0,H23,1E+99),IF(K23>0,K23,1E+99))),G23,J23)))))),0) -> 0
A24: 1 | B24: Pest & Soil Treatment | C24: ='Scope & Phases'!D24 -> x | E24: 450 | F24: 1 | N24: =IFERROR(IF($C24<>"x",0,IF($M24=1,E24,IF($M24=2,H24,IF($M24=3,K24,IF(COUNT(E24,H24,K24)=0,0,MIN(IF(E24>0,E24,1E+99),IF(H24>0,H24,1E+99),IF(K24>0,K24,1E+99))))))),0) -> 450 | O24: =IFERROR(IF($C24<>"x",0,IF($M24=1,F24,IF($M24=2,I24,IF($M24=3,L24,IF(E24=IF(COUNT(E24,H24,K24)=0,0,MIN(IF(E24>0,E24,1E+99),IF(H24>0,H24,1E+99),IF(K24>0,K24,1E+99))),F24,IF(H24=IF(COUNT(E24,H24,K24)=0,0,MIN(IF(E24>0,E24,1E+99),IF(H24>0,H24,1E+99),IF(K24>0,K24,1E+99))),I24,L24)))))),0) -> 1 | P24: =IFERROR(IF($C24<>"x",0,IF($M24=1,D24,IF($M24=2,G24,IF($M24=3,J24,IF(E24=IF(COUNT(E24,H24,K24)=0,0,MIN(IF(E24>0,E24,1E+99),IF(H24>0,H24,1E+99),IF(K24>0,K24,1E+99))),D24,IF(H24=IF(COUNT(E24,H24,K24)=0,0,MIN(IF(E24>0,E24,1E+99),IF(H24>0,H24,1E+99),IF(K24>0,K24,1E+99))),G24,J24)))))),0) -> 0
A25: 2 | B25: Framing Labor | C25: ='Scope & Phases'!D25 -> x | D25: Framing Done Right LLC | E25: 3350 | F25: 6 | N25: =IFERROR(IF($C25<>"x",0,IF($M25=1,E25,IF($M25=2,H25,IF($M25=3,K25,IF(COUNT(E25,H25,K25)=0,0,MIN(IF(E25>0,E25,1E+99),IF(H25>0,H25,1E+99),IF(K25>0,K25,1E+99))))))),0) -> 3350 | O25: =IFERROR(IF($C25<>"x",0,IF($M25=1,F25,IF($M25=2,I25,IF($M25=3,L25,IF(E25=IF(COUNT(E25,H25,K25)=0,0,MIN(IF(E25>0,E25,1E+99),IF(H25>0,H25,1E+99),IF(K25>0,K25,1E+99))),F25,IF(H25=IF(COUNT(E25,H25,K25)=0,0,MIN(IF(E25>0,E25,1E+99),IF(H25>0,H25,1E+99),IF(K25>0,K25,1E+99))),I25,L25)))))),0) -> 6 | P25: =IFERROR(IF($C25<>"x",0,IF($M25=1,D25,IF($M25=2,G25,IF($M25=3,J25,IF(E25=IF(COUNT(E25,H25,K25)=0,0,MIN(IF(E25>0,E25,1E+99),IF(H25>0,H25,1E+99),IF(K25>0,K25,1E+99))),D25,IF(H25=IF(COUNT(E25,H25,K25)=0,0,MIN(IF(E25>0,E25,1E+99),IF(H25>0,H25,1E+99),IF(K25>0,K25,1E+99))),G25,J25)))))),0) -> Framing Done Right LLC
A26: 2 | B26: Framing Material | C26: ='Scope & Phases'!D26 -> x | D26: 84 Lumber | E26: 2725 | F26: 2 | N26: =IFERROR(IF($C26<>"x",0,IF($M26=1,E26,IF($M26=2,H26,IF($M26=3,K26,IF(COUNT(E26,H26,K26)=0,0,MIN(IF(E26>0,E26,1E+99),IF(H26>0,H26,1E+99),IF(K26>0,K26,1E+99))))))),0) -> 2725 | O26: =IFERROR(IF($C26<>"x",0,IF($M26=1,F26,IF($M26=2,I26,IF($M26=3,L26,IF(E26=IF(COUNT(E26,H26,K26)=0,0,MIN(IF(E26>0,E26,1E+99),IF(H26>0,H26,1E+99),IF(K26>0,K26,1E+99))),F26,IF(H26=IF(COUNT(E26,H26,K26)=0,0,MIN(IF(E26>0,E26,1E+99),IF(H26>0,H26,1E+99),IF(K26>0,K26,1E+99))),I26,L26)))))),0) -> 2 | P26: =IFERROR(IF($C26<>"x",0,IF($M26=1,D26,IF($M26=2,G26,IF($M26=3,J26,IF(E26=IF(COUNT(E26,H26,K26)=0,0,MIN(IF(E26>0,E26,1E+99),IF(H26>0,H26,1E+99),IF(K26>0,K26,1E+99))),D26,IF(H26=IF(COUNT(E26,H26,K26)=0,0,MIN(IF(E26>0,E26,1E+99),IF(H26>0,H26,1E+99),IF(K26>0,K26,1E+99))),G26,J26)))))),0) -> 84 Lumber
A27: 2 | B27: Structural Steel & Beams | C27: ='Scope & Phases'!D27 -> 0 | N27: =IFERROR(IF($C27<>"x",0,IF($M27=1,E27,IF($M27=2,H27,IF($M27=3,K27,IF(COUNT(E27,H27,K27)=0,0,MIN(IF(E27>0,E27,1E+99),IF(H27>0,H27,1E+99),IF(K27>0,K27,1E+99))))))),0) -> 0 | O27: =IFERROR(IF($C27<>"x",0,IF($M27=1,F27,IF($M27=2,I27,IF($M27=3,L27,IF(E27=IF(COUNT(E27,H27,K27)=0,0,MIN(IF(E27>0,E27,1E+99),IF(H27>0,H27,1E+99),IF(K27>0,K27,1E+99))),F27,IF(H27=IF(COUNT(E27,H27,K27)=0,0,MIN(IF(E27>0,E27,1E+99),IF(H27>0,H27,1E+99),IF(K27>0,K27,1E+99))),I27,L27)))))),0) -> 0 | P27: =IFERROR(IF($C27<>"x",0,IF($M27=1,D27,IF($M27=2,G27,IF($M27=3,J27,IF(E27=IF(COUNT(E27,H27,K27)=0,0,MIN(IF(E27>0,E27,1E+99),IF(H27>0,H27,1E+99),IF(K27>0,K27,1E+99))),D27,IF(H27=IF(COUNT(E27,H27,K27)=0,0,MIN(IF(E27>0,E27,1E+99),IF(H27>0,H27,1E+99),IF(K27>0,K27,1E+99))),G27,J27)))))),0) -> 0
A28: 2 | B28: Roofing | C28: ='Scope & Phases'!D28 -> x | D28: Sun Valley Roofing | E28: 6950 | F28: 4 | G28: Desert Ridge Roofing | H28: 7925 | I28: 5 | J28: AZ Peak Roofing | K28: 7375 | L28: 3 | N28: =IFERROR(IF($C28<>"x",0,IF($M28=1,E28,IF($M28=2,H28,IF($M28=3,K28,IF(COUNT(E28,H28,K28)=0,0,MIN(IF(E28>0,E28,1E+99),IF(H28>0,H28,1E+99),IF(K28>0,K28,1E+99))))))),0) -> 6950 | O28: =IFERROR(IF($C28<>"x",0,IF($M28=1,F28,IF($M28=2,I28,IF($M28=3,L28,IF(E28=IF(COUNT(E28,H28,K28)=0,0,MIN(IF(E28>0,E28,1E+99),IF(H28>0,H28,1E+99),IF(K28>0,K28,1E+99))),F28,IF(H28=IF(COUNT(E28,H28,K28)=0,0,MIN(IF(E28>0,E28,1E+99),IF(H28>0,H28,1E+99),IF(K28>0,K28,1E+99))),I28,L28)))))),0) -> 4 | P28: =IFERROR(IF($C28<>"x",0,IF($M28=1,D28,IF($M28=2,G28,IF($M28=3,J28,IF(E28=IF(COUNT(E28,H28,K28)=0,0,MIN(IF(E28>0,E28,1E+99),IF(H28>0,H28,1E+99),IF(K28>0,K28,1E+99))),D28,IF(H28=IF(COUNT(E28,H28,K28)=0,0,MIN(IF(E28>0,E28,1E+99),IF(H28>0,H28,1E+99),IF(K28>0,K28,1E+99))),G28,J28)))))),0) -> Sun Valley Roofing
A29: 2 | B29: Windows & Exterior Doors | C29: ='Scope & Phases'!D29 -> x | D29: Arcadia Glass Co | E29: 5450 | F29: 3 | N29: =IFERROR(IF($C29<>"x",0,IF($M29=1,E29,IF($M29=2,H29,IF($M29=3,K29,IF(COUNT(E29,H29,K29)=0,0,MIN(IF(E29>0,E29,1E+99),IF(H29>0,H29,1E+99),IF(K29>0,K29,1E+99))))))),0) -> 5450 | O29: =IFERROR(IF($C29<>"x",0,IF($M29=1,F29,IF($M29=2,I29,IF($M29=3,L29,IF(E29=IF(COUNT(E29,H29,K29)=0,0,MIN(IF(E29>0,E29,1E+99),IF(H29>0,H29,1E+99),IF(K29>0,K29,1E+99))),F29,IF(H29=IF(COUNT(E29,H29,K29)=0,0,MIN(IF(E29>0,E29,1E+99),IF(H29>0,H29,1E+99),IF(K29>0,K29,1E+99))),I29,L29)))))),0) -> 3 | P29: =IFERROR(IF($C29<>"x",0,IF($M29=1,D29,IF($M29=2,G29,IF($M29=3,J29,IF(E29=IF(COUNT(E29,H29,K29)=0,0,MIN(IF(E29>0,E29,1E+99),IF(H29>0,H29,1E+99),IF(K29>0,K29,1E+99))),D29,IF(H29=IF(COUNT(E29,H29,K29)=0,0,MIN(IF(E29>0,E29,1E+99),IF(H29>0,H29,1E+99),IF(K29>0,K29,1E+99))),G29,J29)))))),0) -> Arcadia Glass Co
A30: 2 | B30: Rough Plumbing | C30: ='Scope & Phases'!D30 -> x | D30: Copperline Plumbing | E30: 3875 | F30: 5 | N30: =IFERROR(IF($C30<>"x",0,IF($M30=1,E30,IF($M30=2,H30,IF($M30=3,K30,IF(COUNT(E30,H30,K30)=0,0,MIN(IF(E30>0,E30,1E+99),IF(H30>0,H30,1E+99),IF(K30>0,K30,1E+99))))))),0) -> 3875 | O30: =IFERROR(IF($C30<>"x",0,IF($M30=1,F30,IF($M30=2,I30,IF($M30=3,L30,IF(E30=IF(COUNT(E30,H30,K30)=0,0,MIN(IF(E30>0,E30,1E+99),IF(H30>0,H30,1E+99),IF(K30>0,K30,1E+99))),F30,IF(H30=IF(COUNT(E30,H30,K30)=0,0,MIN(IF(E30>0,E30,1E+99),IF(H30>0,H30,1E+99),IF(K30>0,K30,1E+99))),I30,L30)))))),0) -> 5 | P30: =IFERROR(IF($C30<>"x",0,IF($M30=1,D30,IF($M30=2,G30,IF($M30=3,J30,IF(E30=IF(COUNT(E30,H30,K30)=0,0,MIN(IF(E30>0,E30,1E+99),IF(H30>0,H30,1E+99),IF(K30>0,K30,1E+99))),D30,IF(H30=IF(COUNT(E30,H30,K30)=0,0,MIN(IF(E30>0,E30,1E+99),IF(H30>0,H30,1E+99),IF(K30>0,K30,1E+99))),G30,J30)))))),0) -> Copperline Plumbing
A31: 2 | B31: Rough Electrical | C31: ='Scope & Phases'!D31 -> x | D31: Voltz Electric | E31: 4300 | F31: 6 | G31: Mesa Sparks LLC | H31: 4900 | I31: 7 | J31: Rincon Electrical | K31: 4550 | L31: 5 | N31: =IFERROR(IF($C31<>"x",0,IF($M31=1,E31,IF($M31=2,H31,IF($M31=3,K31,IF(COUNT(E31,H31,K31)=0,0,MIN(IF(E31>0,E31,1E+99),IF(H31>0,H31,1E+99),IF(K31>0,K31,1E+99))))))),0) -> 4300 | O31: =IFERROR(IF($C31<>"x",0,IF($M31=1,F31,IF($M31=2,I31,IF($M31=3,L31,IF(E31=IF(COUNT(E31,H31,K31)=0,0,MIN(IF(E31>0,E31,1E+99),IF(H31>0,H31,1E+99),IF(K31>0,K31,1E+99))),F31,IF(H31=IF(COUNT(E31,H31,K31)=0,0,MIN(IF(E31>0,E31,1E+99),IF(H31>0,H31,1E+99),IF(K31>0,K31,1E+99))),I31,L31)))))),0) -> 6 | P31: =IFERROR(IF($C31<>"x",0,IF($M31=1,D31,IF($M31=2,G31,IF($M31=3,J31,IF(E31=IF(COUNT(E31,H31,K31)=0,0,MIN(IF(E31>0,E31,1E+99),IF(H31>0,H31,1E+99),IF(K31>0,K31,1E+99))),D31,IF(H31=IF(COUNT(E31,H31,K31)=0,0,MIN(IF(E31>0,E31,1E+99),IF(H31>0,H31,1E+99),IF(K31>0,K31,1E+99))),G31,J31)))))),0) -> Voltz Electric
A32: 2 | B32: Rough HVAC | C32: ='Scope & Phases'!D32 -> x | D32: Sonoran Air | E32: 5975 | F32: 4 | N32: =IFERROR(IF($C32<>"x",0,IF($M32=1,E32,IF($M32=2,H32,IF($M32=3,K32,IF(COUNT(E32,H32,K32)=0,0,MIN(IF(E32>0,E32,1E+99),IF(H32>0,H32,1E+99),IF(K32>0,K32,1E+99))))))),0) -> 5975 | O32: =IFERROR(IF($C32<>"x",0,IF($M32=1,F32,IF($M32=2,I32,IF($M32=3,L32,IF(E32=IF(COUNT(E32,H32,K32)=0,0,MIN(IF(E32>0,E32,1E+99),IF(H32>0,H32,1E+99),IF(K32>0,K32,1E+99))),F32,IF(H32=IF(COUNT(E32,H32,K32)=0,0,MIN(IF(E32>0,E32,1E+99),IF(H32>0,H32,1E+99),IF(K32>0,K32,1E+99))),I32,L32)))))),0) -> 4 | P32: =IFERROR(IF($C32<>"x",0,IF($M32=1,D32,IF($M32=2,G32,IF($M32=3,J32,IF(E32=IF(COUNT(E32,H32,K32)=0,0,MIN(IF(E32>0,E32,1E+99),IF(H32>0,H32,1E+99),IF(K32>0,K32,1E+99))),D32,IF(H32=IF(COUNT(E32,H32,K32)=0,0,MIN(IF(E32>0,E32,1E+99),IF(H32>0,H32,1E+99),IF(K32>0,K32,1E+99))),G32,J32)))))),0) -> Sonoran Air
A33: 2 | B33: Low Voltage Rough | C33: ='Scope & Phases'!D33 -> 0 | N33: =IFERROR(IF($C33<>"x",0,IF($M33=1,E33,IF($M33=2,H33,IF($M33=3,K33,IF(COUNT(E33,H33,K33)=0,0,MIN(IF(E33>0,E33,1E+99),IF(H33>0,H33,1E+99),IF(K33>0,K33,1E+99))))))),0) -> 0 | O33: =IFERROR(IF($C33<>"x",0,IF($M33=1,F33,IF($M33=2,I33,IF($M33=3,L33,IF(E33=IF(COUNT(E33,H33,K33)=0,0,MIN(IF(E33>0,E33,1E+99),IF(H33>0,H33,1E+99),IF(K33>0,K33,1E+99))),F33,IF(H33=IF(COUNT(E33,H33,K33)=0,0,MIN(IF(E33>0,E33,1E+99),IF(H33>0,H33,1E+99),IF(K33>0,K33,1E+99))),I33,L33)))))),0) -> 0 | P33: =IFERROR(IF($C33<>"x",0,IF($M33=1,D33,IF($M33=2,G33,IF($M33=3,J33,IF(E33=IF(COUNT(E33,H33,K33)=0,0,MIN(IF(E33>0,E33,1E+99),IF(H33>0,H33,1E+99),IF(K33>0,K33,1E+99))),D33,IF(H33=IF(COUNT(E33,H33,K33)=0,0,MIN(IF(E33>0,E33,1E+99),IF(H33>0,H33,1E+99),IF(K33>0,K33,1E+99))),G33,J33)))))),0) -> 0
A34: 2 | B34: Rough Inspections | C34: ='Scope & Phases'!D34 -> x | E34: 300 | F34: 3 | N34: =IFERROR(IF($C34<>"x",0,IF($M34=1,E34,IF($M34=2,H34,IF($M34=3,K34,IF(COUNT(E34,H34,K34)=0,0,MIN(IF(E34>0,E34,1E+99),IF(H34>0,H34,1E+99),IF(K34>0,K34,1E+99))))))),0) -> 300 | O34: =IFERROR(IF($C34<>"x",0,IF($M34=1,F34,IF($M34=2,I34,IF($M34=3,L34,IF(E34=IF(COUNT(E34,H34,K34)=0,0,MIN(IF(E34>0,E34,1E+99),IF(H34>0,H34,1E+99),IF(K34>0,K34,1E+99))),F34,IF(H34=IF(COUNT(E34,H34,K34)=0,0,MIN(IF(E34>0,E34,1E+99),IF(H34>0,H34,1E+99),IF(K34>0,K34,1E+99))),I34,L34)))))),0) -> 3 | P34: =IFERROR(IF($C34<>"x",0,IF($M34=1,D34,IF($M34=2,G34,IF($M34=3,J34,IF(E34=IF(COUNT(E34,H34,K34)=0,0,MIN(IF(E34>0,E34,1E+99),IF(H34>0,H34,1E+99),IF(K34>0,K34,1E+99))),D34,IF(H34=IF(COUNT(E34,H34,K34)=0,0,MIN(IF(E34>0,E34,1E+99),IF(H34>0,H34,1E+99),IF(K34>0,K34,1E+99))),G34,J34)))))),0) -> 0
A35: 3 | B35: Insulation | C35: ='Scope & Phases'!D35 -> x | D35: Valley Insulation | E35: 1850 | F35: 2 | N35: =IFERROR(IF($C35<>"x",0,IF($M35=1,E35,IF($M35=2,H35,IF($M35=3,K35,IF(COUNT(E35,H35,K35)=0,0,MIN(IF(E35>0,E35,1E+99),IF(H35>0,H35,1E+99),IF(K35>0,K35,1E+99))))))),0) -> 1850 | O35: =IFERROR(IF($C35<>"x",0,IF($M35=1,F35,IF($M35=2,I35,IF($M35=3,L35,IF(E35=IF(COUNT(E35,H35,K35)=0,0,MIN(IF(E35>0,E35,1E+99),IF(H35>0,H35,1E+99),IF(K35>0,K35,1E+99))),F35,IF(H35=IF(COUNT(E35,H35,K35)=0,0,MIN(IF(E35>0,E35,1E+99),IF(H35>0,H35,1E+99),IF(K35>0,K35,1E+99))),I35,L35)))))),0) -> 2 | P35: =IFERROR(IF($C35<>"x",0,IF($M35=1,D35,IF($M35=2,G35,IF($M35=3,J35,IF(E35=IF(COUNT(E35,H35,K35)=0,0,MIN(IF(E35>0,E35,1E+99),IF(H35>0,H35,1E+99),IF(K35>0,K35,1E+99))),D35,IF(H35=IF(COUNT(E35,H35,K35)=0,0,MIN(IF(E35>0,E35,1E+99),IF(H35>0,H35,1E+99),IF(K35>0,K35,1E+99))),G35,J35)))))),0) -> Valley Insulation
A36: 3 | B36: Drywall | C36: ='Scope & Phases'!D36 -> x | D36: Level 5 Drywall | E36: 5625 | F36: 8 | G36: Smooth Wall Co | H36: 6400 | I36: 9 | J36: Canyon Drywall | K36: 5950 | L36: 7 | N36: =IFERROR(IF($C36<>"x",0,IF($M36=1,E36,IF($M36=2,H36,IF($M36=3,K36,IF(COUNT(E36,H36,K36)=0,0,MIN(IF(E36>0,E36,1E+99),IF(H36>0,H36,1E+99),IF(K36>0,K36,1E+99))))))),0) -> 5625 | O36: =IFERROR(IF($C36<>"x",0,IF($M36=1,F36,IF($M36=2,I36,IF($M36=3,L36,IF(E36=IF(COUNT(E36,H36,K36)=0,0,MIN(IF(E36>0,E36,1E+99),IF(H36>0,H36,1E+99),IF(K36>0,K36,1E+99))),F36,IF(H36=IF(COUNT(E36,H36,K36)=0,0,MIN(IF(E36>0,E36,1E+99),IF(H36>0,H36,1E+99),IF(K36>0,K36,1E+99))),I36,L36)))))),0) -> 8 | P36: =IFERROR(IF($C36<>"x",0,IF($M36=1,D36,IF($M36=2,G36,IF($M36=3,J36,IF(E36=IF(COUNT(E36,H36,K36)=0,0,MIN(IF(E36>0,E36,1E+99),IF(H36>0,H36,1E+99),IF(K36>0,K36,1E+99))),D36,IF(H36=IF(COUNT(E36,H36,K36)=0,0,MIN(IF(E36>0,E36,1E+99),IF(H36>0,H36,1E+99),IF(K36>0,K36,1E+99))),G36,J36)))))),0) -> Level 5 Drywall
A37: 3 | B37: Interior Doors | C37: ='Scope & Phases'!D37 -> x | E37: 2025 | F37: 3 | N37: =IFERROR(IF($C37<>"x",0,IF($M37=1,E37,IF($M37=2,H37,IF($M37=3,K37,IF(COUNT(E37,H37,K37)=0,0,MIN(IF(E37>0,E37,1E+99),IF(H37>0,H37,1E+99),IF(K37>0,K37,1E+99))))))),0) -> 2025 | O37: =IFERROR(IF($C37<>"x",0,IF($M37=1,F37,IF($M37=2,I37,IF($M37=3,L37,IF(E37=IF(COUNT(E37,H37,K37)=0,0,MIN(IF(E37>0,E37,1E+99),IF(H37>0,H37,1E+99),IF(K37>0,K37,1E+99))),F37,IF(H37=IF(COUNT(E37,H37,K37)=0,0,MIN(IF(E37>0,E37,1E+99),IF(H37>0,H37,1E+99),IF(K37>0,K37,1E+99))),I37,L37)))))),0) -> 3 | P37: =IFERROR(IF($C37<>"x",0,IF($M37=1,D37,IF($M37=2,G37,IF($M37=3,J37,IF(E37=IF(COUNT(E37,H37,K37)=0,0,MIN(IF(E37>0,E37,1E+99),IF(H37>0,H37,1E+99),IF(K37>0,K37,1E+99))),D37,IF(H37=IF(COUNT(E37,H37,K37)=0,0,MIN(IF(E37>0,E37,1E+99),IF(H37>0,H37,1E+99),IF(K37>0,K37,1E+99))),G37,J37)))))),0) -> 0
A38: 3 | B38: Trim & Millwork | C38: ='Scope & Phases'!D38 -> x | E38: 2550 | F38: 4 | N38: =IFERROR(IF($C38<>"x",0,IF($M38=1,E38,IF($M38=2,H38,IF($M38=3,K38,IF(COUNT(E38,H38,K38)=0,0,MIN(IF(E38>0,E38,1E+99),IF(H38>0,H38,1E+99),IF(K38>0,K38,1E+99))))))),0) -> 2550 | O38: =IFERROR(IF($C38<>"x",0,IF($M38=1,F38,IF($M38=2,I38,IF($M38=3,L38,IF(E38=IF(COUNT(E38,H38,K38)=0,0,MIN(IF(E38>0,E38,1E+99),IF(H38>0,H38,1E+99),IF(K38>0,K38,1E+99))),F38,IF(H38=IF(COUNT(E38,H38,K38)=0,0,MIN(IF(E38>0,E38,1E+99),IF(H38>0,H38,1E+99),IF(K38>0,K38,1E+99))),I38,L38)))))),0) -> 4 | P38: =IFERROR(IF($C38<>"x",0,IF($M38=1,D38,IF($M38=2,G38,IF($M38=3,J38,IF(E38=IF(COUNT(E38,H38,K38)=0,0,MIN(IF(E38>0,E38,1E+99),IF(H38>0,H38,1E+99),IF(K38>0,K38,1E+99))),D38,IF(H38=IF(COUNT(E38,H38,K38)=0,0,MIN(IF(E38>0,E38,1E+99),IF(H38>0,H38,1E+99),IF(K38>0,K38,1E+99))),G38,J38)))))),0) -> 0
A39: 3 | B39: Stairs & Railings | C39: ='Scope & Phases'!D39 -> 0 | N39: =IFERROR(IF($C39<>"x",0,IF($M39=1,E39,IF($M39=2,H39,IF($M39=3,K39,IF(COUNT(E39,H39,K39)=0,0,MIN(IF(E39>0,E39,1E+99),IF(H39>0,H39,1E+99),IF(K39>0,K39,1E+99))))))),0) -> 0 | O39: =IFERROR(IF($C39<>"x",0,IF($M39=1,F39,IF($M39=2,I39,IF($M39=3,L39,IF(E39=IF(COUNT(E39,H39,K39)=0,0,MIN(IF(E39>0,E39,1E+99),IF(H39>0,H39,1E+99),IF(K39>0,K39,1E+99))),F39,IF(H39=IF(COUNT(E39,H39,K39)=0,0,MIN(IF(E39>0,E39,1E+99),IF(H39>0,H39,1E+99),IF(K39>0,K39,1E+99))),I39,L39)))))),0) -> 0 | P39: =IFERROR(IF($C39<>"x",0,IF($M39=1,D39,IF($M39=2,G39,IF($M39=3,J39,IF(E39=IF(COUNT(E39,H39,K39)=0,0,MIN(IF(E39>0,E39,1E+99),IF(H39>0,H39,1E+99),IF(K39>0,K39,1E+99))),D39,IF(H39=IF(COUNT(E39,H39,K39)=0,0,MIN(IF(E39>0,E39,1E+99),IF(H39>0,H39,1E+99),IF(K39>0,K39,1E+99))),G39,J39)))))),0) -> 0
A40: 3 | B40: Interior Paint | C40: ='Scope & Phases'!D40 -> x | D40: Brushworks AZ | E40: 4050 | F40: 5 | N40: =IFERROR(IF($C40<>"x",0,IF($M40=1,E40,IF($M40=2,H40,IF($M40=3,K40,IF(COUNT(E40,H40,K40)=0,0,MIN(IF(E40>0,E40,1E+99),IF(H40>0,H40,1E+99),IF(K40>0,K40,1E+99))))))),0) -> 4050 | O40: =IFERROR(IF($C40<>"x",0,IF($M40=1,F40,IF($M40=2,I40,IF($M40=3,L40,IF(E40=IF(COUNT(E40,H40,K40)=0,0,MIN(IF(E40>0,E40,1E+99),IF(H40>0,H40,1E+99),IF(K40>0,K40,1E+99))),F40,IF(H40=IF(COUNT(E40,H40,K40)=0,0,MIN(IF(E40>0,E40,1E+99),IF(H40>0,H40,1E+99),IF(K40>0,K40,1E+99))),I40,L40)))))),0) -> 5 | P40: =IFERROR(IF($C40<>"x",0,IF($M40=1,D40,IF($M40=2,G40,IF($M40=3,J40,IF(E40=IF(COUNT(E40,H40,K40)=0,0,MIN(IF(E40>0,E40,1E+99),IF(H40>0,H40,1E+99),IF(K40>0,K40,1E+99))),D40,IF(H40=IF(COUNT(E40,H40,K40)=0,0,MIN(IF(E40>0,E40,1E+99),IF(H40>0,H40,1E+99),IF(K40>0,K40,1E+99))),G40,J40)))))),0) -> Brushworks AZ
A41: 4 | B41: Kitchen Cabinets | C41: ='Scope & Phases'!D41 -> x | D41: Copper State Cabinets | E41: 6075 | F41: 4 | G41: Mesa Cabinet Works | H41: 6925 | I41: 5 | J41: Sundance Millwork | K41: 6450 | L41: 3 | N41: =IFERROR(IF($C41<>"x",0,IF($M41=1,E41,IF($M41=2,H41,IF($M41=3,K41,IF(COUNT(E41,H41,K41)=0,0,MIN(IF(E41>0,E41,1E+99),IF(H41>0,H41,1E+99),IF(K41>0,K41,1E+99))))))),0) -> 6075 | O41: =IFERROR(IF($C41<>"x",0,IF($M41=1,F41,IF($M41=2,I41,IF($M41=3,L41,IF(E41=IF(COUNT(E41,H41,K41)=0,0,MIN(IF(E41>0,E41,1E+99),IF(H41>0,H41,1E+99),IF(K41>0,K41,1E+99))),F41,IF(H41=IF(COUNT(E41,H41,K41)=0,0,MIN(IF(E41>0,E41,1E+99),IF(H41>0,H41,1E+99),IF(K41>0,K41,1E+99))),I41,L41)))))),0) -> 4 | P41: =IFERROR(IF($C41<>"x",0,IF($M41=1,D41,IF($M41=2,G41,IF($M41=3,J41,IF(E41=IF(COUNT(E41,H41,K41)=0,0,MIN(IF(E41>0,E41,1E+99),IF(H41>0,H41,1E+99),IF(K41>0,K41,1E+99))),D41,IF(H41=IF(COUNT(E41,H41,K41)=0,0,MIN(IF(E41>0,E41,1E+99),IF(H41>0,H41,1E+99),IF(K41>0,K41,1E+99))),G41,J41)))))),0) -> Copper State Cabinets
A42: 4 | B42: Bath Vanities | C42: ='Scope & Phases'!D42 -> x | E42: 1625 | F42: 2 | N42: =IFERROR(IF($C42<>"x",0,IF($M42=1,E42,IF($M42=2,H42,IF($M42=3,K42,IF(COUNT(E42,H42,K42)=0,0,MIN(IF(E42>0,E42,1E+99),IF(H42>0,H42,1E+99),IF(K42>0,K42,1E+99))))))),0) -> 1625 | O42: =IFERROR(IF($C42<>"x",0,IF($M42=1,F42,IF($M42=2,I42,IF($M42=3,L42,IF(E42=IF(COUNT(E42,H42,K42)=0,0,MIN(IF(E42>0,E42,1E+99),IF(H42>0,H42,1E+99),IF(K42>0,K42,1E+99))),F42,IF(H42=IF(COUNT(E42,H42,K42)=0,0,MIN(IF(E42>0,E42,1E+99),IF(H42>0,H42,1E+99),IF(K42>0,K42,1E+99))),I42,L42)))))),0) -> 2 | P42: =IFERROR(IF($C42<>"x",0,IF($M42=1,D42,IF($M42=2,G42,IF($M42=3,J42,IF(E42=IF(COUNT(E42,H42,K42)=0,0,MIN(IF(E42>0,E42,1E+99),IF(H42>0,H42,1E+99),IF(K42>0,K42,1E+99))),D42,IF(H42=IF(COUNT(E42,H42,K42)=0,0,MIN(IF(E42>0,E42,1E+99),IF(H42>0,H42,1E+99),IF(K42>0,K42,1E+99))),G42,J42)))))),0) -> 0
A43: 4 | B43: Laundry & Utility Cabinets | C43: ='Scope & Phases'!D43 -> x | E43: 675 | F43: 1 | N43: =IFERROR(IF($C43<>"x",0,IF($M43=1,E43,IF($M43=2,H43,IF($M43=3,K43,IF(COUNT(E43,H43,K43)=0,0,MIN(IF(E43>0,E43,1E+99),IF(H43>0,H43,1E+99),IF(K43>0,K43,1E+99))))))),0) -> 675 | O43: =IFERROR(IF($C43<>"x",0,IF($M43=1,F43,IF($M43=2,I43,IF($M43=3,L43,IF(E43=IF(COUNT(E43,H43,K43)=0,0,MIN(IF(E43>0,E43,1E+99),IF(H43>0,H43,1E+99),IF(K43>0,K43,1E+99))),F43,IF(H43=IF(COUNT(E43,H43,K43)=0,0,MIN(IF(E43>0,E43,1E+99),IF(H43>0,H43,1E+99),IF(K43>0,K43,1E+99))),I43,L43)))))),0) -> 1 | P43: =IFERROR(IF($C43<>"x",0,IF($M43=1,D43,IF($M43=2,G43,IF($M43=3,J43,IF(E43=IF(COUNT(E43,H43,K43)=0,0,MIN(IF(E43>0,E43,1E+99),IF(H43>0,H43,1E+99),IF(K43>0,K43,1E+99))),D43,IF(H43=IF(COUNT(E43,H43,K43)=0,0,MIN(IF(E43>0,E43,1E+99),IF(H43>0,H43,1E+99),IF(K43>0,K43,1E+99))),G43,J43)))))),0) -> 0
...

Sheet Budget & Schedule
A1: Budget & Schedule
A2: Your bids, rolled up. Phases run one after another; jobs inside a phase run together.
A5: Total rehab budget | D5: =SUMIF('Scope & Phases'!$D$8:$D$73,"x",'Scope & Phases'!$E$8:$E$73) -> 129325
A6: Cost per square foot | D6: =IFERROR('Budget & Schedule'!$D$5/'Your Deal'!$D$9,0) -> 69.52957
A7: Calendar days on site | D7: =IFERROR(MAX(G12:G25)-'Your Deal'!$D$31+1,0) -> 155
A8: Months of carry | D8: =IFERROR('Budget & Schedule'!$D$7/30.44,0) -> 5.0919842
A11: Ph | B11: Phase | C11: Jobs | D11: Budget | E11: Days | F11: Starts | G11: Finishes
A12: A | B12: Pre-Construction & General Conditions | C12: =COUNTIFS('Scope & Phases'!$A$8:$A$73,"A",'Scope & Phases'!$D$8:$D$73,"x") -> 6 | D12: =SUMIFS('Scope & Phases'!$E$8:$E$73,'Scope & Phases'!$A$8:$A$73,"A",'Scope & Phases'!$D$8:$D$73,"x") -> 14925 | E12: =IFERROR(SUMIFS('Scope & Phases'!$F$8:$F$73,'Scope & Phases'!$A$8:$A$73,"A",'Scope & Phases'!$D$8:$D$73,"x"),0) -> 16 | F12: ='Your Deal'!$D$31 -> 46314 | G12: =IF(E12=0,F12-1,F12+E12-1) -> 46329
A13: 1 | B13: Demolition, Foundation & Underground | C13: =COUNTIFS('Scope & Phases'!$A$8:$A$73,"1",'Scope & Phases'!$D$8:$D$73,"x") -> 3 | D13: =SUMIFS('Scope & Phases'!$E$8:$E$73,'Scope & Phases'!$A$8:$A$73,"1",'Scope & Phases'!$D$8:$D$73,"x") -> 6000 | E13: =IFERROR(SUMIFS('Scope & Phases'!$F$8:$F$73,'Scope & Phases'!$A$8:$A$73,"1",'Scope & Phases'!$D$8:$D$73,"x"),0) -> 9 | F13: =G12+1 -> 46330 | G13: =IF(E13=0,F13-1,F13+E13-1) -> 46338
A14: 2 | B14: Framing, Roofing & Rough MEP | C14: =COUNTIFS('Scope & Phases'!$A$8:$A$73,"2",'Scope & Phases'!$D$8:$D$73,"x") -> 8 | D14: =SUMIFS('Scope & Phases'!$E$8:$E$73,'Scope & Phases'!$A$8:$A$73,"2",'Scope & Phases'!$D$8:$D$73,"x") -> 32925 | E14: =IFERROR(SUMIFS('Scope & Phases'!$F$8:$F$73,'Scope & Phases'!$A$8:$A$73,"2",'Scope & Phases'!$D$8:$D$73,"x"),0) -> 33 | F14: =G13+1 -> 46339 | G14: =IF(E14=0,F14-1,F14+E14-1) -> 46371
A15: 3 | B15: Insulation, Drywall, Doors, Trim & Paint | C15: =COUNTIFS('Scope & Phases'!$A$8:$A$73,"3",'Scope & Phases'!$D$8:$D$73,"x") -> 5 | D15: =SUMIFS('Scope & Phases'!$E$8:$E$73,'Scope & Phases'!$A$8:$A$73,"3",'Scope & Phases'!$D$8:$D$73,"x") -> 16100 | E15: =IFERROR(SUMIFS('Scope & Phases'!$F$8:$F$73,'Scope & Phases'!$A$8:$A$73,"3",'Scope & Phases'!$D$8:$D$73,"x"),0) -> 22 | F15: =G14+1 -> 46372 | G15: =IF(E15=0,F15-1,F15+E15-1) -> 46393
A16: 4 | B16: Cabinets & Countertops | C16: =COUNTIFS('Scope & Phases'!$A$8:$A$73,"4",'Scope & Phases'!$D$8:$D$73,"x") -> 5 | D16: =SUMIFS('Scope & Phases'!$E$8:$E$73,'Scope & Phases'!$A$8:$A$73,"4",'Scope & Phases'!$D$8:$D$73,"x") -> 12625 | E16: =IFERROR(SUMIFS('Scope & Phases'!$F$8:$F$73,'Scope & Phases'!$A$8:$A$73,"4",'Scope & Phases'!$D$8:$D$73,"x"),0) -> 11 | F16: =G15+1 -> 46394 | G16: =IF(E16=0,F16-1,F16+E16-1) -> 46404
A17: 5 | B17: Tile & Flooring | C17: =COUNTIFS('Scope & Phases'!$A$8:$A$73,"5",'Scope & Phases'!$D$8:$D$73,"x") -> 6 | D17: =SUMIFS('Scope & Phases'!$E$8:$E$73,'Scope & Phases'!$A$8:$A$73,"5",'Scope & Phases'!$D$8:$D$73,"x") -> 13050 | E17: =IFERROR(SUMIFS('Scope & Phases'!$F$8:$F$73,'Scope & Phases'!$A$8:$A$73,"5",'Scope & Phases'!$D$8:$D$73,"x"),0) -> 17 | F17: =G16+1 -> 46405 | G17: =IF(E17=0,F17-1,F17+E17-1) -> 46421
A18: 6 | B18: Exterior & Landscaping | C18: =COUNTIFS('Scope & Phases'!$A$8:$A$73,"6",'Scope & Phases'!$D$8:$D$73,"x") -> 6 | D18: =SUMIFS('Scope & Phases'!$E$8:$E$73,'Scope & Phases'!$A$8:$A$73,"6",'Scope & Phases'!$D$8:$D$73,"x") -> 14500 | E18: =IFERROR(SUMIFS('Scope & Phases'!$F$8:$F$73,'Scope & Phases'!$A$8:$A$73,"6",'Scope & Phases'!$D$8:$D$73,"x"),0) -> 22 | F18: =G17+1 -> 46422 | G18: =IF(E18=0,F18-1,F18+E18-1) -> 46443
A19: 7 | B19: MEP Finishes, Glass & Appliances | C19: =COUNTIFS('Scope & Phases'!$A$8:$A$73,"7",'Scope & Phases'!$D$8:$D$73,"x") -> 8 | D19: =SUMIFS('Scope & Phases'!$E$8:$E$73,'Scope & Phases'!$A$8:$A$73,"7",'Scope & Phases'!$D$8:$D$73,"x") -> 12075 | E19: =IFERROR(SUMIFS('Scope & Phases'!$F$8:$F$73,'Scope & Phases'!$A$8:$A$73,"7",'Scope & Phases'!$D$8:$D$73,"x"),0) -> 15 | F19: =G18+1 -> 46444 | G19: =IF(E19=0,F19-1,F19+E19-1) -> 46458
A20: 8 | B20: Punch, Carpet & Final Clean | C20: =COUNTIFS('Scope & Phases'!$A$8:$A$73,"8",'Scope & Phases'!$D$8:$D$73,"x") -> 5 | D20: =SUMIFS('Scope & Phases'!$E$8:$E$73,'Scope & Phases'!$A$8:$A$73,"8",'Scope & Phases'!$D$8:$D$73,"x") -> 7125 | E20: =IFERROR(SUMIFS('Scope & Phases'!$F$8:$F$73,'Scope & Phases'!$A$8:$A$73,"8",'Scope & Phases'!$D$8:$D$73,"x"),0) -> 10 | F20: =G19+1 -> 46459 | G20: =IF(E20=0,F20-1,F20+E20-1) -> 46468
B21: TOTAL | C21: =COUNTIF('Scope & Phases'!$D$8:$D$73,"x") -> 52 | D21: =SUM(D12:D20) -> 129325 | G21: =MAX(G12:G20) -> 46468
A23: A phase takes as long as its jobs added together. On a house this size one trade works at a time.
A24: Days come from what each sub quoted on the Bid Comparison sheet — they are calendar days, not working days.

Sheet Draw Schedule
A1: Draw Schedule
A2: One draw per phase. Request when the phase finishes; the money lands later.
A6: The gap between 'Request on' and 'Funded on' is the number of days you told us your lender takes.
A8: Draw | B8: Phase | C8: Phase budget | D8: Holdback | E8: You receive | F8: Request on | G8: Funded on
A9: 1 | B9: ='Budget & Schedule'!B12 -> Pre-Construction & General Conditions | C9: ='Budget & Schedule'!D12 -> 14925 | D9: =-C9*'Your Deal'!$D$35 -> -1492.5 | E9: =C9+D9 -> 13432.5 | F9: ='Budget & Schedule'!G12 -> 46329 | G9: =IF(C9=0,"",F9+'Your Deal'!$D$24) -> 46339
A10: 2 | B10: ='Budget & Schedule'!B13 -> Demolition, Foundation & Underground | C10: ='Budget & Schedule'!D13 -> 6000 | D10: =-C10*'Your Deal'!$D$35 -> -600 | E10: =C10+D10 -> 5400 | F10: ='Budget & Schedule'!G13 -> 46338 | G10: =IF(C10=0,"",F10+'Your Deal'!$D$24) -> 46348
A11: 3 | B11: ='Budget & Schedule'!B14 -> Framing, Roofing & Rough MEP | C11: ='Budget & Schedule'!D14 -> 32925 | D11: =-C11*'Your Deal'!$D$35 -> -3292.5 | E11: =C11+D11 -> 29632.5 | F11: ='Budget & Schedule'!G14 -> 46371 | G11: =IF(C11=0,"",F11+'Your Deal'!$D$24) -> 46381
A12: 4 | B12: ='Budget & Schedule'!B15 -> Insulation, Drywall, Doors, Trim & Paint | C12: ='Budget & Schedule'!D15 -> 16100 | D12: =-C12*'Your Deal'!$D$35 -> -1610 | E12: =C12+D12 -> 14490 | F12: ='Budget & Schedule'!G15 -> 46393 | G12: =IF(C12=0,"",F12+'Your Deal'!$D$24) -> 46403
A13: 5 | B13: ='Budget & Schedule'!B16 -> Cabinets & Countertops | C13: ='Budget & Schedule'!D16 -> 12625 | D13: =-C13*'Your Deal'!$D$35 -> -1262.5 | E13: =C13+D13 -> 11362.5 | F13: ='Budget & Schedule'!G16 -> 46404 | G13: =IF(C13=0,"",F13+'Your Deal'!$D$24) -> 46414
A14: 6 | B14: ='Budget & Schedule'!B17 -> Tile & Flooring | C14: ='Budget & Schedule'!D17 -> 13050 | D14: =-C14*'Your Deal'!$D$35 -> -1305 | E14: =C14+D14 -> 11745 | F14: ='Budget & Schedule'!G17 -> 46421 | G14: =IF(C14=0,"",F14+'Your Deal'!$D$24) -> 46431
A15: 7 | B15: ='Budget & Schedule'!B18 -> Exterior & Landscaping | C15: ='Budget & Schedule'!D18 -> 14500 | D15: =-C15*'Your Deal'!$D$35 -> -1450 | E15: =C15+D15 -> 13050 | F15: ='Budget & Schedule'!G18 -> 46443 | G15: =IF(C15=0,"",F15+'Your Deal'!$D$24) -> 46453
A16: 8 | B16: ='Budget & Schedule'!B19 -> MEP Finishes, Glass & Appliances | C16: ='Budget & Schedule'!D19 -> 12075 | D16: =-C16*'Your Deal'!$D$35 -> -1207.5 | E16: =C16+D16 -> 10867.5 | F16: ='Budget & Schedule'!G19 -> 46458 | G16: =IF(C16=0,"",F16+'Your Deal'!$D$24) -> 46468
A17: 9 | B17: ='Budget & Schedule'!B20 -> Punch, Carpet & Final Clean | C17: ='Budget & Schedule'!D20 -> 7125 | D17: =-C17*'Your Deal'!$D$35 -> -712.5 | E17: =C17+D17 -> 6412.5 | F17: ='Budget & Schedule'!G20 -> 46468 | G17: =IF(C17=0,"",F17+'Your Deal'!$D$24) -> 46478
B18: TOTAL | C18: =SUM(C9:C17) -> 129325 | D18: =SUM(D9:D17) -> -12932.5 | E18: =SUM(E9:E17) -> 116392.5
A20: Holdback is released at completion. Until then it is money you have spent and not been paid for.

Sheet Cash & Float
A1: Cash & Float
A2: What this job costs you to carry between paying subs and getting funded.
A6: You pay a deposit when a phase starts and the balance when it finishes. The draw arrives days after that.
A9: Ph | B9: Phase | C9: Deposit out | D9: Balance out | E9: Draw in | F9: On this date | G9: Cash position
A10: A | B10: ='Budget & Schedule'!B12 -> Pre-Construction & General Conditions | C10: =-'Budget & Schedule'!D12*'Your Deal'!$D$33 -> -7462.5 | D10: =-'Budget & Schedule'!D12*(1-'Your Deal'!$D$33) -> -7462.5 | E10: ='Draw Schedule'!E9 -> 13432.5 | F10: ='Budget & Schedule'!G12 -> 46329 | G10: ='Your Deal'!$D$26+SUMIF($F$10:$F$18,"<="&$F10,$C$10:$C$18)+SUMIF($F$10:$F$18,"<="&$F10,$D$10:$D$18)+SUMIF('Draw Schedule'!$G$9:$G$17,"<="&$F10,'Draw Schedule'!$E$9:$E$17) -> 45075
A11: 1 | B11: ='Budget & Schedule'!B13 -> Demolition, Foundation & Underground | C11: =-'Budget & Schedule'!D13*'Your Deal'!$D$33 -> -3000 | D11: =-'Budget & Schedule'!D13*(1-'Your Deal'!$D$33) -> -3000 | E11: ='Draw Schedule'!E10 -> 5400 | F11: ='Budget & Schedule'!G13 -> 46338 | G11: ='Your Deal'!$D$26+SUMIF($F$10:$F$18,"<="&$F11,$C$10:$C$18)+SUMIF($F$10:$F$18,"<="&$F11,$D$10:$D$18)+SUMIF('Draw Schedule'!$G$9:$G$17,"<="&$F11,'Draw Schedule'!$E$9:$E$17) -> 39075
A12: 2 | B12: ='Budget & Schedule'!B14 -> Framing, Roofing & Rough MEP | C12: =-'Budget & Schedule'!D14*'Your Deal'!$D$33 -> -16462.5 | D12: =-'Budget & Schedule'!D14*(1-'Your Deal'!$D$33) -> -16462.5 | E12: ='Draw Schedule'!E11 -> 29632.5 | F12: ='Budget & Schedule'!G14 -> 46371 | G12: ='Your Deal'!$D$26+SUMIF($F$10:$F$18,"<="&$F12,$C$10:$C$18)+SUMIF($F$10:$F$18,"<="&$F12,$D$10:$D$18)+SUMIF('Draw Schedule'!$G$9:$G$17,"<="&$F12,'Draw Schedule'!$E$9:$E$17) -> 24982.5
A13: 3 | B13: ='Budget & Schedule'!B15 -> Insulation, Drywall, Doors, Trim & Paint | C13: =-'Budget & Schedule'!D15*'Your Deal'!$D$33 -> -8050 | D13: =-'Budget & Schedule'!D15*(1-'Your Deal'!$D$33) -> -8050 | E13: ='Draw Schedule'!E12 -> 14490 | F13: ='Budget & Schedule'!G15 -> 46393 | G13: ='Your Deal'!$D$26+SUMIF($F$10:$F$18,"<="&$F13,$C$10:$C$18)+SUMIF($F$10:$F$18,"<="&$F13,$D$10:$D$18)+SUMIF('Draw Schedule'!$G$9:$G$17,"<="&$F13,'Draw Schedule'!$E$9:$E$17) -> 38515
A14: 4 | B14: ='Budget & Schedule'!B16 -> Cabinets & Countertops | C14: =-'Budget & Schedule'!D16*'Your Deal'!$D$33 -> -6312.5 | D14: =-'Budget & Schedule'!D16*(1-'Your Deal'!$D$33) -> -6312.5 | E14: ='Draw Schedule'!E13 -> 11362.5 | F14: ='Budget & Schedule'!G16 -> 46404 | G14: ='Your Deal'!$D$26+SUMIF($F$10:$F$18,"<="&$F14,$C$10:$C$18)+SUMIF($F$10:$F$18,"<="&$F14,$D$10:$D$18)+SUMIF('Draw Schedule'!$G$9:$G$17,"<="&$F14,'Draw Schedule'!$E$9:$E$17) -> 40380
A15: 5 | B15: ='Budget & Schedule'!B17 -> Tile & Flooring | C15: =-'Budget & Schedule'!D17*'Your Deal'!$D$33 -> -6525 | D15: =-'Budget & Schedule'!D17*(1-'Your Deal'!$D$33) -> -6525 | E15: ='Draw Schedule'!E14 -> 11745 | F15: ='Budget & Schedule'!G17 -> 46421 | G15: ='Your Deal'!$D$26+SUMIF($F$10:$F$18,"<="&$F15,$C$10:$C$18)+SUMIF($F$10:$F$18,"<="&$F15,$D$10:$D$18)+SUMIF('Draw Schedule'!$G$9:$G$17,"<="&$F15,'Draw Schedule'!$E$9:$E$17) -> 38692.5
